<?xml version="1.0"?>

<!--
Base to shoulder yaw:
dX = 201
dY = 205

Shoulder yaw to shoulder pitch:
dX = 129mm

Shoulder pitch to knee pitch:
dX = 329mm

Knee pitch to foot:
dX = 482mm (joint to foot center)
dX = 512mm (joint to tip)

-->

<!--Parameters
x_0 = 0.201
y_0 = 0.205
z_0 = 0.0


-->

<sdf version='1.7'>
    <model name="Tetrapod">
        <pose>0 0 1 0 0 0</pose>
        <static>false</static>

        <link name="body">
            <pose>0 0 0 0 0 0</pose>

            <inertial>
                <pose>0 0 0 0 0 0</pose>
                <mass>10.0</mass>
                <inertia>
                <ixx>1.0</ixx>
                <ixy>0</ixy>
                <ixz>0</ixz>
                <iyy>1.0</iyy>
                <iyz>0.0</iyz>
                <izz>1.0</izz>
                </inertia>
            </inertial>

            <visual name="body_visual">
                <geometry>
                    <mesh>
                        <uri>model://tetrapod_description/Meshes/base.dae</uri>
                    </mesh>  
                </geometry>
            </visual>
            <collision name="body_collision">
                <geometry>
                    <box>
                        <size>0.5 0.5 0.15</size>
                    </box>
                </geometry>
            </collision>
        </link>


<!-- FRONT LEFT LEG -->

        <link name="front_left_hip">
            <!-- Let the pose of the link coincide with the joint position -->
            <!--
                x = x_0
                y = y_0
                z = z_0
                r = 0
                p = 0
                y = 0
            -->
            <pose>0.201 0.205 0 0 0 0</pose>

            <inertial>
                <!-- Position of front_left_hip CoM relative to joint position. Obtained from Solidworks-->
                <pose>0 0.0 0 0 0 0</pose>

                <mass>1.0</mass>
                <inertia>
                <ixx>0.1</ixx>
                <ixy>0</ixy>
                <ixz>0</ixz>
                <iyy>0.1</iyy>
                <iyz>0.0</iyz>
                <izz>0.1</izz>
                </inertia>
            </inertial>

            <visual name="front_left_hip_visual">
                <geometry>
                    <mesh>
                        <uri>model://tetrapod_description/Meshes/left_shoulder.dae</uri>
                    </mesh>  
                </geometry>
            </visual>

        </link>

        <joint name="front_left_hip_yaw" type="revolute">
            <!-- Use zero as joint and link position coincide-->
            <pose>0 0 0 0 0 0</pose> 

            <child>front_left_hip</child>
            <parent>body</parent>
            <axis>
                <xyz>0 0 1</xyz>
                <limit>
                    <lower>0</lower>
                    <upper>3.14</upper>
                    <effort>30</effort>
                    <velocity>1000</velocity>
                </limit>
            </axis>
        </joint>

        <link name="front_left_upper_leg">
            <!-- Let the pose of the link coincide with the hip pitch joint position -->
            <!--
                x = x_0 + r1
                y = y_0
                z = z_0 + d1
                r = -1.5708 (rotate the leg)
                p = 0
                y = 0
            -->
            <pose>0.330 0.201 0 -1.5708 0 0</pose>

            <collision name="front_left_upper_leg_collision">
                <!-- Add pose for collision-->
                <pose>0.1645 0 0 0 1.5708 0</pose>
                <geometry>
                    <cylinder>
                        <radius>0.01</radius>
                        <length>0.329</length>
                    </cylinder>
                </geometry>
            </collision>
            <visual name="front_left_upper_leg">
                <pose>0 0 0 0 0 0</pose>
                <geometry>
                    <mesh>
                        <uri>model://tetrapod_description/Meshes/upper_leg.dae</uri>
                    </mesh>                    
                </geometry>
            </visual>
            <inertial>
                <!-- Position of upper_leg CoM relative to hip pitch joint position. Obtained from Solidworks-->
                <pose>0 0 0 0 0 0</pose>
                <mass>1.0</mass>
                <inertia>
                <ixx>0.1</ixx>
                <ixy>0</ixy>
                <ixz>0</ixz>
                <iyy>0.1</iyy>
                <iyz>0.0</iyz>
                <izz>0.1</izz>
                </inertia>
            </inertial>
        </link>

        <joint name="front_left_hip_pitch" type="revolute">
            <parent>front_left_hip</parent>
            <child>front_left_upper_leg</child>
            <!-- Use zero as joint and link position coincide-->
            <pose frame="front_left_hip">0 0 0 0 0 0</pose>
            <axis>
                <xyz>0 0 1</xyz>
                <limit>
                    <lower>-2.5</lower>
                    <upper>2.5</upper>
                    <effort>30</effort>
                    <velocity>1000</velocity>
                </limit>
            </axis>
        </joint>

        <link name="front_left_lower_leg">
            <!-- Let the pose of the link coincide with the knee pitch joint position -->
            <!--
                x = x_0 + r1 + r2
                y = y_0
                z = z_0 + d1
                r = -1.5708
                p = 0
                y = 0
            -->
            <pose>0.659 0.205 0 -1.5708 0 0</pose>
            <visual name="front_left_lower_leg_visual">
                <pose>0 0 0 0 0 0</pose>
                <geometry>
                    <mesh>
                        <uri>model://tetrapod_description/Meshes/lower_leg.dae</uri>
                    </mesh>
                </geometry>
            </visual>
            <collision name="front_left_lower_leg_collision">
                <!-- Add pose for collision-->
                <pose>0.241 0 0 0 1.5708 0</pose>
                <geometry>
                    <cylinder>
                        <radius>0.01</radius>
                        <length>0.482</length>
                    </cylinder>
                </geometry>
            </collision>
            <collision name="front_left_knee_collision">
                <geometry>
                    <cylinder>
                        <radius>0.035</radius>
                        <length>0.06</length>
                    </cylinder>
                </geometry>
            </collision>
            <inertial>
                <!-- Position of lower_leg CoM relative to knee pitch joint position. Obtained from Solidworks-->
                <pose>0 0 0 0 0 0</pose>
                <mass>1.0</mass>
                <inertia>
                <ixx>0.1</ixx>
                <ixy>0</ixy>
                <ixz>0</ixz>
                <iyy>0.1</iyy>
                <iyz>0.0</iyz>
                <izz>0.1</izz>
                </inertia>
            </inertial>
        </link>

        <joint name="front_left_knee_joint" type="revolute">
            <parent>front_left_upper_leg</parent>
            <child>front_left_lower_leg</child>
            <pose>0 0 0 0 0 0</pose>
            <axis>
                <xyz>0 0 1</xyz>
                <limit>
                    <lower>-2.5</lower>
                    <upper>2.5</upper>
                    <effort>30</effort>
                    <velocity>1000</velocity>
                </limit>
            </axis> 
        </joint>

        <link name="front_left_foot">
            <!-- Let the pose of the link coincide with the foot position -->
            <!--
                x = x_0 + r1 + r2 + r3
                y = y_0
                z = z_0 + d1
                r = 1.5708
                p = 0
                y = 0
            -->
            <pose>1.141 0.205 0 1.5708 0 0</pose>

            <inertial>
                <pose>0 0 0 0 0 0</pose>
                <mass>0.1</mass>
                <inertia>
                    <ixx>0.01</ixx>
                    <ixy>0</ixy>
                    <ixz>0</ixz>
                    <iyy>0.01</iyy>
                    <iyz>0.0</iyz>
                    <izz>0.01</izz>
                </inertia>
            </inertial>
            <collision name="front_left_foot_collision">
                <geometry>
                    <sphere>
                        <radius>0.03</radius>
                    </sphere>
                </geometry>
                <surface>
                    <friction>
                        <ode>
                            <mu>0.7</mu>
                        </ode>
                    </friction>
                </surface>
            </collision>
        </link>

        <joint name="front_left_foot_joint" type="fixed">
            <parent>front_left_lower_leg</parent>
            <child>front_left_foot</child>
            <pose>0 0 0 0 0 0</pose>
        </joint>



<!-- FRONT RIGHT LEG -->

        <link name="front_right_hip">
            <!-- Let the pose of the link coincide with the joint position -->
            <!--
                x = x_0
                y = -y_0
                z = z_0
                r = 0
                p = 0
                y = 0
            -->
            <pose>0.201 -0.205 0 0 0 0</pose>

            <inertial>
                <!-- Position of front_right_hip CoM relative to joint position. Obtained from Solidworks-->
                <pose>0 0.0 0 0 0 0</pose>

                <mass>1.0</mass>
                <inertia>
                <ixx>0.1</ixx>
                <ixy>0</ixy>
                <ixz>0</ixz>
                <iyy>0.1</iyy>
                <iyz>0.0</iyz>
                <izz>0.1</izz>
                </inertia>
            </inertial>

            <visual name="front_right_hip_visual">
                <geometry>
                    <mesh>
                        <uri>model://tetrapod_description/Meshes/right_shoulder.dae</uri>
                    </mesh>  
                </geometry>
            </visual>

        </link>

        <joint name="front_right_hip_yaw" type="revolute">
            <!-- Use zero as joint and link position coincide-->
            <pose>0 0 0 0 0 0</pose> 

            <child>front_right_hip</child>
            <parent>body</parent>
            <axis>
                <xyz>0 0 1</xyz>
                <limit>
                    <lower>-3.14</lower>
                    <upper>0.0</upper>
                    <effort>30</effort>
                    <velocity>1000</velocity>
                </limit>
            </axis>
        </joint>

        <link name="front_right_upper_leg">
            <!-- Let the pose of the link coincide with the hip pitch joint position -->
            <!--
                x = x_0 + r1
                y = -y_0
                z = z_0 + d1
                r = 1.5708 (rotate the leg)
                p = 0
                y = 0
            -->
            <pose>0.330 -0.201 0 1.5708 0 0</pose>

            <collision name="front_right_upper_leg_collision">
                <!-- Add pose for collision-->
                <pose>0.1645 0 0 0 1.5708 0</pose>
                <geometry>
                    <cylinder>
                        <radius>0.01</radius>
                        <length>0.329</length>
                    </cylinder>
                </geometry>
            </collision>
            <visual name="front_right_upper_leg">
                <pose>0 0 0 0 0 0</pose>
                <geometry>
                    <mesh>
                        <uri>model://tetrapod_description/Meshes/upper_leg.dae</uri>
                    </mesh>                    
                </geometry>
            </visual>
            <inertial>
                <!-- Position of upper_leg CoM relative to hip pitch joint position. Obtained from Solidworks-->
                <pose>0 0 0 0 0 0</pose>
                <mass>1.0</mass>
                <inertia>
                <ixx>0.1</ixx>
                <ixy>0</ixy>
                <ixz>0</ixz>
                <iyy>0.1</iyy>
                <iyz>0.0</iyz>
                <izz>0.1</izz>
                </inertia>
            </inertial>
        </link>

        <joint name="front_right_hip_pitch" type="revolute">
            <parent>front_right_hip</parent>
            <child>front_right_upper_leg</child>
            <!-- Use zero as joint and link position coincide-->
            <pose frame="front_right_hip">0 0 0 0 0 0</pose>
            <axis>
                <xyz>0 0 1</xyz>
                <limit>
                    <lower>-2.5</lower>
                    <upper>2.5</upper>
                    <effort>30</effort>
                    <velocity>1000</velocity>
                </limit>
            </axis>
        </joint>

        <link name="front_right_lower_leg">
            <!-- Let the pose of the link coincide with the knee pitch joint position -->
            <!--
                x = x_0 + r1 + r2
                y = -y_0
                z = z_0 + d1
                r = 1.5708
                p = 0
                y = 0
            -->
            <pose>0.659 -0.205 0 1.5708 0 0</pose>
            <visual name="front_right_lower_leg_visual">
                <pose>0 0 0 0 0 0</pose>
                <geometry>
                    <mesh>
                        <uri>model://tetrapod_description/Meshes/lower_leg.dae</uri>
                    </mesh>
                </geometry>
            </visual>
            <collision name="front_right_lower_leg_collision">
                <!-- Add pose for collision-->
                <pose>0.241 0 0 0 1.5708 0</pose>
                <geometry>
                    <cylinder>
                        <radius>0.01</radius>
                        <length>0.482</length>
                    </cylinder>
                </geometry>
            </collision>
            <collision name="front_right_knee_collision">
                <geometry>
                    <cylinder>
                        <radius>0.035</radius>
                        <length>0.06</length>
                    </cylinder>
                </geometry>
            </collision>
            <inertial>
                <!-- Position of lower_leg CoM relative to knee pitch joint position. Obtained from Solidworks-->
                <pose>0 0 0 0 0 0</pose>
                <mass>1.0</mass>
                <inertia>
                <ixx>0.1</ixx>
                <ixy>0</ixy>
                <ixz>0</ixz>
                <iyy>0.1</iyy>
                <iyz>0.0</iyz>
                <izz>0.1</izz>
                </inertia>
            </inertial>
        </link>

        <joint name="front_right_knee_joint" type="revolute">
            <parent>front_right_upper_leg</parent>
            <child>front_right_lower_leg</child>
            <pose>0 0 0 0 0 0</pose>
            <axis>
                <xyz>0 0 1</xyz>
                <limit>
                    <lower>-2.5</lower>
                    <upper>2.5</upper>
                    <effort>30</effort>
                    <velocity>1000</velocity>
                </limit>
            </axis> 
        </joint>

        <link name="front_right_foot">
            <!-- Let the pose of the link coincide with the foot position -->
            <!--
                x = x_0 + r1 + r2 + r3
                y = -y_0
                z = z_0 + d1
                r = 1.5708
                p = 0
                y = 0
            -->
            <pose>1.141 -0.205 0 1.5708 0 0</pose>

            <inertial>
                <pose>0 0 0 0 0 0</pose>
                <mass>0.1</mass>
                <inertia>
                    <ixx>0.01</ixx>
                    <ixy>0</ixy>
                    <ixz>0</ixz>
                    <iyy>0.01</iyy>
                    <iyz>0.0</iyz>
                    <izz>0.01</izz>
                </inertia>
            </inertial>
            <collision name="front_right_foot_collision">
                <geometry>
                    <sphere>
                        <radius>0.03</radius>
                    </sphere>
                </geometry>
                <surface>
                    <friction>
                        <ode>
                            <mu>0.7</mu>
                        </ode>
                    </friction>
                </surface>
            </collision>
        </link>

        <joint name="front_right_foot_joint" type="fixed">
            <parent>front_right_lower_leg</parent>
            <child>front_right_foot</child>
            <pose>0 0 0 0 0 0</pose>
        </joint>



<!-- REAR LEFT LEG -->

        <link name="rear_left_hip">
            <!-- Let the pose of the link coincide with the joint position -->
            <!--
                x = -x_0
                y = y_0
                z = z_0
                r = 0
                p = 0
                y = 0
            -->
            <pose>-0.201 0.205 0 0 0 0</pose>

            <inertial>
                <!-- Position of rear_left_hip CoM relative to joint position. Obtained from Solidworks-->
                <pose>0 0.0 0 0 0 0</pose>

                <mass>1.0</mass>
                <inertia>
                <ixx>0.1</ixx>
                <ixy>0</ixy>
                <ixz>0</ixz>
                <iyy>0.1</iyy>
                <iyz>0.0</iyz>
                <izz>0.1</izz>
                </inertia>
            </inertial>

            <visual name="rear_left_hip_visual">
                <geometry>
                    <mesh>
                        <uri>model://tetrapod_description/Meshes/right_shoulder.dae</uri>
                    </mesh>  
                </geometry>
            </visual>

        </link>

        <joint name="rear_left_hip_yaw" type="revolute">
            <!-- Use zero as joint and link position coincide-->
            <pose>0 0 0 0 0 0</pose> 

            <child>rear_left_hip</child>
            <parent>body</parent>
            <axis>
                <xyz>0 0 1</xyz>
                <limit>
                    <lower>0</lower>
                    <upper>3.14</upper>
                    <effort>30</effort>
                    <velocity>1000</velocity>
                </limit>
            </axis>
        </joint>

        <link name="rear_left_upper_leg">
            <!-- Let the pose of the link coincide with the hip pitch joint position -->
            <!--
                x = -x_0 + r1
                y = y_0
                z = z_0 + d1
                r = 1.5708 (rotate the leg)
                p = 0
                y = 0
            -->
            <pose>-0.072 0.201 0 1.5708 0 0</pose>

            <collision name="rear_left_upper_leg_collision">
                <!-- Add pose for collision-->
                <pose>0.1645 0 0 0 1.5708 0</pose>
                <geometry>
                    <cylinder>
                        <radius>0.01</radius>
                        <length>0.329</length>
                    </cylinder>
                </geometry>
            </collision>
            <visual name="rear_left_upper_leg">
                <pose>0 0 0 0 0 0</pose>
                <geometry>
                    <mesh>
                        <uri>model://tetrapod_description/Meshes/upper_leg.dae</uri>
                    </mesh>                    
                </geometry>
            </visual>
            <inertial>
                <!-- Position of upper_leg CoM relative to hip pitch joint position. Obtained from Solidworks-->
                <pose>0 0 0 0 0 0</pose>
                <mass>1.0</mass>
                <inertia>
                <ixx>0.1</ixx>
                <ixy>0</ixy>
                <ixz>0</ixz>
                <iyy>0.1</iyy>
                <iyz>0.0</iyz>
                <izz>0.1</izz>
                </inertia>
            </inertial>
        </link>

        <joint name="rear_left_hip_pitch" type="revolute">
            <parent>rear_left_hip</parent>
            <child>rear_left_upper_leg</child>
            <!-- Use zero as joint and link position coincide-->
            <pose frame="rear_left_hip">0 0 0 0 0 0</pose>
            <axis>
                <xyz>0 0 1</xyz>
                <limit>
                    <lower>-2.5</lower>
                    <upper>2.5</upper>
                    <effort>30</effort>
                    <velocity>1000</velocity>
                </limit>
            </axis>
        </joint>

        <link name="rear_left_lower_leg">
            <!-- Let the pose of the link coincide with the knee pitch joint position -->
            <!--
                x = -x_0 + r1 + r2
                y = y_0
                z = z_0 + d1
                r = 1.5708
                p = 0
                y = 0
            -->
            <pose>0.257 0.205 0 1.5708 0 0</pose>
            <visual name="rear_left_lower_leg_visual">
                <pose>0 0 0 0 0 0</pose>
                <geometry>
                    <mesh>
                        <uri>model://tetrapod_description/Meshes/lower_leg.dae</uri>
                    </mesh>
                </geometry>
            </visual>
            <collision name="rear_left_lower_leg_collision">
                <!-- Add pose for collision-->
                <pose>0.241 0 0 0 1.5708 0</pose>
                <geometry>
                    <cylinder>
                        <radius>0.01</radius>
                        <length>0.482</length>
                    </cylinder>
                </geometry>
            </collision>
            <collision name="rear_left_knee_collision">
                <geometry>
                    <cylinder>
                        <radius>0.035</radius>
                        <length>0.06</length>
                    </cylinder>
                </geometry>
            </collision>
            <inertial>
                <!-- Position of lower_leg CoM relative to knee pitch joint position. Obtained from Solidworks-->
                <pose>0 0 0 0 0 0</pose>
                <mass>1.0</mass>
                <inertia>
                    <ixx>0.1</ixx>
                    <ixy>0</ixy>
                    <ixz>0</ixz>
                    <iyy>0.1</iyy>
                    <iyz>0.0</iyz>
                    <izz>0.1</izz>
                </inertia>
            </inertial>
        </link>

        <joint name="rear_left_knee_joint" type="revolute">
            <parent>rear_left_upper_leg</parent>
            <child>rear_left_lower_leg</child>
            <pose>0 0 0 0 0 0</pose>
            <axis>
                <xyz>0 0 1</xyz>
                <limit>
                    <lower>-2.5</lower>
                    <upper>2.5</upper>
                    <effort>30</effort>
                    <velocity>1000</velocity>
                </limit>
            </axis> 
        </joint>

        <link name="rear_left_foot">
            <!-- Let the pose of the link coincide with the foot position -->
            <!--
                x = x_0 + r1 + r2 + r3
                y = y_0
                z = z_0 + d1
                r = 1.5708
                p = 0
                y = 0
            -->
            <pose>0.739 0.205 0 1.5708 0 0</pose>

            <inertial>
                <pose>0 0 0 0 0 0</pose>
                <mass>0.1</mass>
                <inertia>
                    <ixx>0.01</ixx>
                    <ixy>0</ixy>
                    <ixz>0</ixz>
                    <iyy>0.01</iyy>
                    <iyz>0.0</iyz>
                    <izz>0.01</izz>
                </inertia>
            </inertial>
            <collision name="rear_left_foot_collision">
                <geometry>
                    <sphere>
                        <radius>0.03</radius>
                    </sphere>
                </geometry>
                <surface>
                    <friction>
                        <ode>
                            <mu>0.7</mu>
                        </ode>
                    </friction>
                </surface>
            </collision>
        </link>

        <joint name="rear_left_foot_joint" type="fixed">
            <parent>rear_left_lower_leg</parent>
            <child>rear_left_foot</child>
            <pose>0 0 0 0 0 0</pose>
        </joint>



<!-- REAR RIGHT LEG -->

        <link name="rear_right_hip">
            <!-- Let the pose of the link coincide with the joint position -->
            <!--
                x = -x_0
                y = -y_0
                z = z_0
                r = 0
                p = 0
                y = 0
            -->
            <pose>-0.201 -0.205 0 0 0 0</pose>

            <inertial>
                <!-- Position of rear_right_hip CoM relative to joint position. Obtained from Solidworks-->
                <pose>0 0.0 0 0 0 0</pose>

                <mass>1.0</mass>
                <inertia>
                <ixx>0.1</ixx>
                <ixy>0</ixy>
                <ixz>0</ixz>
                <iyy>0.1</iyy>
                <iyz>0.0</iyz>
                <izz>0.1</izz>
                </inertia>
            </inertial>

            <visual name="rear_right_hip_visual">
                <geometry>
                    <mesh>
                        <uri>model://tetrapod_description/Meshes/left_shoulder.dae</uri>
                    </mesh>  
                </geometry>
            </visual>
        </link>

        <joint name="rear_right_hip_yaw" type="revolute">
            <!-- Use zero as joint and link position coincide-->
            <pose>0 0 0 0 0 0</pose> 

            <child>rear_right_hip</child>
            <parent>body</parent>
            <axis>
                <xyz>0 0 1</xyz>
                <limit>
                    <lower>-3.14</lower>
                    <upper>0.0</upper>
                    <effort>30</effort>
                    <velocity>1000</velocity>
                </limit>
            </axis>
        </joint>

        <link name="rear_right_upper_leg">
            <!-- Let the pose of the link coincide with the hip pitch joint position -->
            <!--
                x = -x_0 + r1
                y = -y_0
                z = z_0 + d1
                r = -1.5708 (rotate the leg)
                p = 0
                y = 0
            -->
            <pose>-0.072 -0.201 0 -1.5708 0 0</pose>

            <collision name="rear_right_upper_leg_collision">
                <!-- Add pose for collision-->
                <pose>0.1645 0 0 0 1.5708 0</pose>
                <geometry>
                    <cylinder>
                        <radius>0.01</radius>
                        <length>0.329</length>
                    </cylinder>
                </geometry>
            </collision>
            <visual name="rear_right_upper_leg">
                <pose>0 0 0 0 0 0</pose>
                <geometry>
                    <mesh>
                        <uri>model://tetrapod_description/Meshes/upper_leg.dae</uri>
                    </mesh>                    
                </geometry>
            </visual>
            <inertial>
                <!-- Position of upper_leg CoM relative to hip pitch joint position. Obtained from Solidworks-->
                <pose>0 0 0 0 0 0</pose>
                <mass>1.0</mass>
                <inertia>
                <ixx>0.1</ixx>
                <ixy>0</ixy>
                <ixz>0</ixz>
                <iyy>0.1</iyy>
                <iyz>0.0</iyz>
                <izz>0.1</izz>
                </inertia>
            </inertial>
        </link>

        <joint name="rear_right_hip_pitch" type="revolute">
            <parent>rear_right_hip</parent>
            <child>rear_right_upper_leg</child>
            <!-- Use zero as joint and link position coincide-->
            <pose frame="rear_right_hip">0 0 0 0 0 0</pose>
            <axis>
                <xyz>0 0 1</xyz>
                <limit>
                    <lower>-2.5</lower>
                    <upper>2.5</upper>
                    <effort>30</effort>
                    <velocity>1000</velocity>
                </limit>
            </axis>
        </joint>

        <link name="rear_right_lower_leg">
            <!-- Let the pose of the link coincide with the knee pitch joint position -->
            <!--
                x = -x_0 + r1 + r2
                y = y_0
                z = z_0 + d1
                r = 1.5708
                p = 0
                y = 0
            -->
            <pose>0.257 -0.205 0 -1.5708 0 0</pose>
            <visual name="rear_right_lower_leg_visual">
                <pose>0 0 0 0 0 0</pose>
                <geometry>
                    <mesh>
                        <uri>model://tetrapod_description/Meshes/lower_leg.dae</uri>
                    </mesh>
                </geometry>
            </visual>
            <collision name="rear_right_lower_leg_collision">
                <!-- Add pose for collision-->
                <pose>0.241 0 0 0 1.5708 0</pose>
                <geometry>
                    <cylinder>
                        <radius>0.01</radius>
                        <length>0.482</length>
                    </cylinder>
                </geometry>
            </collision>
            <collision name="rear_right_knee_collision">
                <geometry>
                    <cylinder>
                        <radius>0.035</radius>
                        <length>0.06</length>
                    </cylinder>
                </geometry>
            </collision>
            <inertial>
                <!-- Position of lower_leg CoM relative to knee pitch joint position. Obtained from Solidworks-->
                <pose>0 0 0 0 0 0</pose>
                <mass>1.0</mass>
                <inertia>
                    <ixx>0.1</ixx>
                    <ixy>0</ixy>
                    <ixz>0</ixz>
                    <iyy>0.1</iyy>
                    <iyz>0.0</iyz>
                    <izz>0.1</izz>
                </inertia>
            </inertial>
        </link>

        <joint name="rear_right_knee_joint" type="revolute">
            <parent>rear_right_upper_leg</parent>
            <child>rear_right_lower_leg</child>
            <pose>0 0 0 0 0 0</pose>
            <axis>
                <xyz>0 0 1</xyz>
                <limit>
                    <lower>-2.5</lower>
                    <upper>2.5</upper>
                    <effort>30</effort>
                    <velocity>1000</velocity>
                </limit>
            </axis> 
        </joint>

        <link name="rear_right_foot">
            <!-- Let the pose of the link coincide with the foot position -->
            <!--
                x = -x_0 + r1 + r2 + r3
                y = -y_0
                z = z_0 + d1
                r = 1.5708
                p = 0
                y = 0
            -->
            <pose>0.739 -0.205 0 -1.5708 0 0</pose>

            <inertial>
                <pose>0 0 0 0 0 0</pose>
                <mass>0.1</mass>
                <inertia>
                    <ixx>0.01</ixx>
                    <ixy>0</ixy>
                    <ixz>0</ixz>
                    <iyy>0.01</iyy>
                    <iyz>0.0</iyz>
                    <izz>0.01</izz>
                </inertia>
            </inertial>
            <collision name="rear_right_foot_collision">
                <geometry>
                    <sphere>
                        <radius>0.03</radius>
                    </sphere>
                </geometry>
                <surface>
                    <friction>
                        <ode>
                            <mu>0.7</mu>
                        </ode>
                    </friction>
                </surface>
            </collision>
        </link>

        <joint name="rear_right_foot_joint" type="fixed">
            <parent>rear_right_lower_leg</parent>
            <child>rear_right_foot</child>
            <pose>0 0 0 0 0 0</pose>
        </joint>

    </model>
</sdf>