<?xml version="1.0" ?>
<!-- =================================================================================== -->
<!-- |    This document was autogenerated by xacro from src/simulator/ASTRo_urdf/ASTRo_xacro/ASTRo_figure.urdf.xacro | -->
<!-- |    EDITING THIS FILE BY HAND IS NOT RECOMMENDED                                 | -->
<!-- =================================================================================== -->
<!-- 
MIT License (modified)
Copyright (c) 2018 Ghost Robotics
Authors:
Avik De <avik@ghostrobotics.io>
Tom Jacobs <tom.jacobs@ghostrobotics.io>
Vasileios Vasilopoulos <v.vasilo@ghostrobotics.io>
Permission is hereby granted, free of charge, to any person obtaining a copy
of this **file** (the "Software"), to deal
in the Software without restriction, including without limitation the rights
to use, copy, modify, merge, publish, distribute, sublicense, and/or sell
copies of the Software, and to permit persons to whom the Software is
furnished to do so, subject to the following conditions:
The above copyright notice and this permission notice shall be included in all
copies or substantial portions of the Software.
THE SOFTWARE IS PROVIDED "AS IS", WITHOUT WARRANTY OF ANY KIND, EXPRESS OR
IMPLIED, INCLUDING BUT NOT LIMITED TO THE WARRANTIES OF MERCHANTABILITY,
FITNESS FOR A PARTICULAR PURPOSE AND NONINFRINGEMENT. IN NO EVENT SHALL THE
AUTHORS OR COPYRIGHT HOLDERS BE LIABLE FOR ANY CLAIM, DAMAGES OR OTHER
LIABILITY, WHETHER IN AN ACTION OF CONTRACT, TORT OR OTHERWISE, ARISING FROM,
OUT OF OR IN CONNECTION WITH THE SOFTWARE OR THE USE OR OTHER DEALINGS IN THE
SOFTWARE. 
-->
<robot name="ASTRo">
  <material name="gray">
    <color rgba="0.5 0.5 0.5 1.0"/>
  </material>
  <!-- Body -->
  <link name="base">
    <visual>
      <origin rpy="0 0 0" xyz="0 0 0"/>
      <geometry>
        <box size="0.35 0.35 0.1"/>
      </geometry>
      <material name="gray"/>
    </visual>
    <inertial>
      <mass value="10.1"/>
      <!-- Uniform box -->
      <inertia ixx="0.141" ixy="0" ixz="0" iyy="0.143" iyz="0" izz="0.254"/>
    </inertial>
    <!-- Just copy geometry for collision -->
    <collision>
      <geometry>
        <box size="0.35 0.35 0.1"/>
      </geometry>
    </collision>
  </link>
  <gazebo reference="base">
    <material>Gazebo/BlackTransparent</material>
  </gazebo>
  <!-- red new legs -->
  <!-- TODO: clean this, it should be part of main leg macro -->
  <!-- Hip motor -->
  <link name="hip1,fl">
    <visual>
      <origin rpy="0 0 0" xyz="0.065 0.03 0"/>
      <geometry>
        <box size="0.13 0.09 0.07"/>
      </geometry>
      <material name="gray"/>
    </visual>
    <collision>
      <origin rpy="0 0 0" xyz="0.065 0.03 0"/>
      <geometry>
        <box size="0.13 0.09 0.07"/>
      </geometry>
    </collision>
    <inertial>
      <mass value="1.18"/>
      <inertia ixx="0.0299" ixy="0" ixz="0" iyy="0.0333" iyz="0" izz="0.0046"/>
    </inertial>
  </link>
  <gazebo reference="hip1,fl">
    <material>Gazebo/Purple</material>
  </gazebo>
  <!-- Abduction joint. Joint names are: 8 9 10 11 -->
  <joint name="8" type="revolute">
    <parent link="base"/>
    <child link="hip1,fl"/>
    <axis xyz="0 0 1"/>
    <origin rpy="0 0 0.0" xyz="0.15121 0.15121 0"/>
    <limit effort="375" lower="-0.39269908169872414" upper="1.5707963267948966" velocity="8.6"/>
    <dynamics damping="0.0" friction="0.0"/>
  </joint>
  <!-- Transmission elements required for Gazebo -->
  <transmission name="transmission_8">
    <type>transmission_interface/SimpleTransmission</type>
    <joint name="8">
      <hardwareInterface>hardware_interface/EffortJointInterface</hardwareInterface>
    </joint>
    <actuator name="motor_8">
      <hardwareInterface>EffortJointInterface</hardwareInterface>
      <mechanicalReduction>1</mechanicalReduction>
    </actuator>
  </transmission>
  <!-- Upper leg -->
  <link name="hip2,fl">
    <visual>
      <origin rpy="1.5707963267948966 0 0" xyz="0.111 0 -0.03"/>
      <geometry>
        <box size="0.222 0.044 0.06"/>
      </geometry>
      <material name="gray"/>
    </visual>
    <collision>
      <origin rpy="0 0 0" xyz="0.111 0 -0.03"/>
      <geometry>
        <box size="0.222 0.044 0.06"/>
      </geometry>
    </collision>
    <inertial>
      <mass value="1.39"/>
      <inertia ixx="0.0017" ixy="0" ixz="0" iyy="0.0066" iyz="0" izz="0.0064"/>
    </inertial>
  </link>
  <gazebo reference="hip2,fl">
    <material>Gazebo/Blue</material>
  </gazebo>
  <!-- Hip joint. (Motor to upper leg). Joint names are: 0 2 4 6 -->
  <joint name="0" type="revolute">
    <parent link="hip1,fl"/>
    <child link="hip2,fl"/>
    <axis xyz="0 0 1"/>
    <origin rpy="-1.5707963267948966 0 0" xyz="0.13 0.03 0"/>
    <limit effort="87.5" lower="-1.5707963267948966" upper="2.356194490192345" velocity="30"/>
    <dynamics damping="0.0" friction="0.0"/>
  </joint>
  <!-- Transmission elements required for Gazebo -->
  <transmission name="transmission_0">
    <type>transmission_interface/SimpleTransmission</type>
    <joint name="0">
      <hardwareInterface>hardware_interface/EffortJointInterface</hardwareInterface>
    </joint>
    <actuator name="motor_0">
      <hardwareInterface>EffortJointInterface</hardwareInterface>
      <mechanicalReduction>1</mechanicalReduction>
    </actuator>
  </transmission>
  <!-- Lower leg -->
  <link name="knee,fl">
    <visual>
      <origin rpy="1.5707963267948966 0 1.5707963267948966" xyz="0.135 0 0"/>
      <geometry>
        <cylinder length="0.27" radius="0.011"/>
      </geometry>
      <material name="gray"/>
    </visual>
    <collision>
      <origin rpy="1.5707963267948966 0 1.5707963267948966" xyz="0.135 0 -0.0"/>
      <geometry>
        <cylinder length="0.27" radius="0.011"/>
      </geometry>
    </collision>
    <inertial>
      <mass value="0.28"/>
      <inertia ixx="0.0665" ixy="0" ixz="0" iyy="0.0032" iyz="0" izz="0.0032"/>
    </inertial>
  </link>
  <gazebo reference="knee,fl">
    <material>Gazebo/Black</material>
  </gazebo>
  <!-- Knee joint. Joint names are: 1 3 5 7 -->
  <joint name="1" type="revolute">
    <parent link="hip2,fl"/>
    <child link="knee,fl"/>
    <axis xyz="0 0 -1"/>
    <origin rpy="0 0 3.141592653589793" xyz="0.222 0 -0.03"/>
    <limit effort="87.5" lower="0" upper="3.141592653589793" velocity="30"/>
    <dynamics damping="0.0" friction="0.0"/>
  </joint>
  <!-- Transmission elements required for Gazebo -->
  <transmission name="transmission_1">
    <type>transmission_interface/SimpleTransmission</type>
    <joint name="1">
      <hardwareInterface>hardware_interface/EffortJointInterface</hardwareInterface>
    </joint>
    <actuator name="motor_1">
      <hardwareInterface>EffortJointInterface</hardwareInterface>
      <mechanicalReduction>1</mechanicalReduction>
    </actuator>
  </transmission>
  

		Toe 
		
  <link name="foot,fl">
    <!--<visual>
				<origin rpy="0 0 0" xyz="0 0 0"/>
				<geometry>
					<sphere radius="${toeRadius}"/>
				</geometry>
			</visual>
			
			<collision>
				<origin rpy="0 0 0" xyz="0 0 0"/>
				<geometry>
					<sphere radius="${toeRadius}"/>
				</geometry>
			</collision>

			<inertial>
				<mass value="${toeMass}"/>
				<inertia ixx="0.000025"  ixy="0"  ixz="0" iyy="0.000025" iyz="0" izz="0.000025" />
			</inertial>
			-->
  </link>
  <gazebo reference="foot,fl">
    <material>Gazebo/DarkGray</material>
    <collision>
      <surface>
        <bounce>
          <restitution_coefficient>0</restitution_coefficient>
          <threshold>1e+06</threshold>
        </bounce>
        <friction>
          <torsional>
            <coefficient>0.3</coefficient>
          </torsional>
          <ode>
            <mu>20.0</mu>
            <mu2>10.0</mu2>
          </ode>
          <bullet>
            <rolling_friction>0.3</rolling_friction>
            <friction2>10.0</friction2>
          </bullet>
        </friction>
        <contact>
          <bullet>
            <kp>30000.0</kp>
            <kd>1000.0</kd>
          </bullet>
          <ode>
            <kp>30000.0</kp>
            <kd>1000.0</kd>
          </ode>
        </contact>
      </surface>
    </collision>
  </gazebo>
  <joint name="jtoe,fl" type="fixed">
    <parent link="knee,fl"/>
    <child link="foot,fl"/>
    <origin xyz="0.27 0 0"/>
    <dynamics damping="0.0" friction="0.0"/>
  </joint>
  <!-- Hip motor -->
  <link name="hip1,rl">
    <visual>
      <origin rpy="0 0 0" xyz="0.065 -0.03 0"/>
      <geometry>
        <box size="0.13 0.09 0.07"/>
      </geometry>
      <material name="gray"/>
    </visual>
    <collision>
      <origin rpy="0 0 0" xyz="0.065 -0.03 0"/>
      <geometry>
        <box size="0.13 0.09 0.07"/>
      </geometry>
    </collision>
    <inertial>
      <mass value="1.18"/>
      <inertia ixx="0.0299" ixy="0" ixz="0" iyy="0.0333" iyz="0" izz="0.0046"/>
    </inertial>
  </link>
  <gazebo reference="hip1,rl">
    <material>Gazebo/Purple</material>
  </gazebo>
  <!-- Abduction joint. Joint names are: 8 9 10 11 -->
  <joint name="9" type="revolute">
    <parent link="base"/>
    <child link="hip1,rl"/>
    <axis xyz="0 0 1"/>
    <origin rpy="0 0 3.141592653589793" xyz="-0.15121 0.15121 0"/>
    <limit effort="375" lower="-1.5707963267948966" upper="0.39269908169872414" velocity="8.6"/>
    <dynamics damping="0.0" friction="0.0"/>
  </joint>
  <!-- Transmission elements required for Gazebo -->
  <transmission name="transmission_9">
    <type>transmission_interface/SimpleTransmission</type>
    <joint name="9">
      <hardwareInterface>hardware_interface/EffortJointInterface</hardwareInterface>
    </joint>
    <actuator name="motor_9">
      <hardwareInterface>EffortJointInterface</hardwareInterface>
      <mechanicalReduction>1</mechanicalReduction>
    </actuator>
  </transmission>
  <!-- Upper leg -->
  <link name="hip2,rl">
    <visual>
      <origin rpy="1.5707963267948966 0 0" xyz="0.111 0 0.03"/>
      <geometry>
        <box size="0.222 0.044 0.06"/>
      </geometry>
      <material name="gray"/>
    </visual>
    <collision>
      <origin rpy="0 0 0" xyz="0.111 0 0.03"/>
      <geometry>
        <box size="0.222 0.044 0.06"/>
      </geometry>
    </collision>
    <inertial>
      <mass value="1.39"/>
      <inertia ixx="0.0017" ixy="0" ixz="0" iyy="0.0066" iyz="0" izz="0.0064"/>
    </inertial>
  </link>
  <gazebo reference="hip2,rl">
    <material>Gazebo/Blue</material>
  </gazebo>
  <!-- Hip joint. (Motor to upper leg). Joint names are: 0 2 4 6 -->
  <joint name="2" type="revolute">
    <parent link="hip1,rl"/>
    <child link="hip2,rl"/>
    <axis xyz="0 0 1"/>
    <origin rpy="-1.5707963267948966 0 0" xyz="0.13 -0.03 0"/>
    <limit effort="87.5" lower="-1.5707963267948966" upper="2.356194490192345" velocity="30"/>
    <dynamics damping="0.0" friction="0.0"/>
  </joint>
  <!-- Transmission elements required for Gazebo -->
  <transmission name="transmission_2">
    <type>transmission_interface/SimpleTransmission</type>
    <joint name="2">
      <hardwareInterface>hardware_interface/EffortJointInterface</hardwareInterface>
    </joint>
    <actuator name="motor_2">
      <hardwareInterface>EffortJointInterface</hardwareInterface>
      <mechanicalReduction>1</mechanicalReduction>
    </actuator>
  </transmission>
  <!-- Lower leg -->
  <link name="knee,rl">
    <visual>
      <origin rpy="1.5707963267948966 0 1.5707963267948966" xyz="0.135 0 0"/>
      <geometry>
        <cylinder length="0.27" radius="0.011"/>
      </geometry>
      <material name="gray"/>
    </visual>
    <collision>
      <origin rpy="1.5707963267948966 0 1.5707963267948966" xyz="0.135 0 -0.0"/>
      <geometry>
        <cylinder length="0.27" radius="0.011"/>
      </geometry>
    </collision>
    <inertial>
      <mass value="0.28"/>
      <inertia ixx="0.0665" ixy="0" ixz="0" iyy="0.0032" iyz="0" izz="0.0032"/>
    </inertial>
  </link>
  <gazebo reference="knee,rl">
    <material>Gazebo/Black</material>
  </gazebo>
  <!-- Knee joint. Joint names are: 1 3 5 7 -->
  <joint name="3" type="revolute">
    <parent link="hip2,rl"/>
    <child link="knee,rl"/>
    <axis xyz="0 0 -1"/>
    <origin rpy="0 0 3.141592653589793" xyz="0.222 0 0.03"/>
    <limit effort="87.5" lower="0" upper="3.141592653589793" velocity="30"/>
    <dynamics damping="0.0" friction="0.0"/>
  </joint>
  <!-- Transmission elements required for Gazebo -->
  <transmission name="transmission_3">
    <type>transmission_interface/SimpleTransmission</type>
    <joint name="3">
      <hardwareInterface>hardware_interface/EffortJointInterface</hardwareInterface>
    </joint>
    <actuator name="motor_3">
      <hardwareInterface>EffortJointInterface</hardwareInterface>
      <mechanicalReduction>1</mechanicalReduction>
    </actuator>
  </transmission>
  

		Toe 
		
  <link name="foot,rl">
    <!--<visual>
				<origin rpy="0 0 0" xyz="0 0 0"/>
				<geometry>
					<sphere radius="${toeRadius}"/>
				</geometry>
			</visual>
			
			<collision>
				<origin rpy="0 0 0" xyz="0 0 0"/>
				<geometry>
					<sphere radius="${toeRadius}"/>
				</geometry>
			</collision>

			<inertial>
				<mass value="${toeMass}"/>
				<inertia ixx="0.000025"  ixy="0"  ixz="0" iyy="0.000025" iyz="0" izz="0.000025" />
			</inertial>
			-->
  </link>
  <gazebo reference="foot,rl">
    <material>Gazebo/DarkGray</material>
    <collision>
      <surface>
        <bounce>
          <restitution_coefficient>0</restitution_coefficient>
          <threshold>1e+06</threshold>
        </bounce>
        <friction>
          <torsional>
            <coefficient>0.3</coefficient>
          </torsional>
          <ode>
            <mu>20.0</mu>
            <mu2>10.0</mu2>
          </ode>
          <bullet>
            <rolling_friction>0.3</rolling_friction>
            <friction2>10.0</friction2>
          </bullet>
        </friction>
        <contact>
          <bullet>
            <kp>30000.0</kp>
            <kd>1000.0</kd>
          </bullet>
          <ode>
            <kp>30000.0</kp>
            <kd>1000.0</kd>
          </ode>
        </contact>
      </surface>
    </collision>
  </gazebo>
  <joint name="jtoe,rl" type="fixed">
    <parent link="knee,rl"/>
    <child link="foot,rl"/>
    <origin xyz="0.27 0 0"/>
    <dynamics damping="0.0" friction="0.0"/>
  </joint>
  <!-- Hip motor -->
  <link name="hip1,fr">
    <visual>
      <origin rpy="0 0 0" xyz="0.065 -0.03 0"/>
      <geometry>
        <box size="0.13 0.09 0.07"/>
      </geometry>
      <material name="gray"/>
    </visual>
    <collision>
      <origin rpy="0 0 0" xyz="0.065 -0.03 0"/>
      <geometry>
        <box size="0.13 0.09 0.07"/>
      </geometry>
    </collision>
    <inertial>
      <mass value="1.18"/>
      <inertia ixx="0.0299" ixy="0" ixz="0" iyy="0.0333" iyz="0" izz="0.0046"/>
    </inertial>
  </link>
  <gazebo reference="hip1,fr">
    <material>Gazebo/Purple</material>
  </gazebo>
  <!-- Abduction joint. Joint names are: 8 9 10 11 -->
  <joint name="10" type="revolute">
    <parent link="base"/>
    <child link="hip1,fr"/>
    <axis xyz="0 0 1"/>
    <origin rpy="0 0 0.0" xyz="0.15121 -0.15121 0"/>
    <limit effort="375" lower="-1.5707963267948966" upper="0.39269908169872414" velocity="8.6"/>
    <dynamics damping="0.0" friction="0.0"/>
  </joint>
  <!-- Transmission elements required for Gazebo -->
  <transmission name="transmission_10">
    <type>transmission_interface/SimpleTransmission</type>
    <joint name="10">
      <hardwareInterface>hardware_interface/EffortJointInterface</hardwareInterface>
    </joint>
    <actuator name="motor_10">
      <hardwareInterface>EffortJointInterface</hardwareInterface>
      <mechanicalReduction>1</mechanicalReduction>
    </actuator>
  </transmission>
  <!-- Upper leg -->
  <link name="hip2,fr">
    <visual>
      <origin rpy="1.5707963267948966 0 0" xyz="0.111 0 0.03"/>
      <geometry>
        <box size="0.222 0.044 0.06"/>
      </geometry>
      <material name="gray"/>
    </visual>
    <collision>
      <origin rpy="0 0 0" xyz="0.111 0 0.03"/>
      <geometry>
        <box size="0.222 0.044 0.06"/>
      </geometry>
    </collision>
    <inertial>
      <mass value="1.39"/>
      <inertia ixx="0.0017" ixy="0" ixz="0" iyy="0.0066" iyz="0" izz="0.0064"/>
    </inertial>
  </link>
  <gazebo reference="hip2,fr">
    <material>Gazebo/Blue</material>
  </gazebo>
  <!-- Hip joint. (Motor to upper leg). Joint names are: 0 2 4 6 -->
  <joint name="4" type="revolute">
    <parent link="hip1,fr"/>
    <child link="hip2,fr"/>
    <axis xyz="0 0 1"/>
    <origin rpy="-1.5707963267948966 0 0" xyz="0.13 -0.03 0"/>
    <limit effort="87.5" lower="-1.5707963267948966" upper="2.356194490192345" velocity="30"/>
    <dynamics damping="0.0" friction="0.0"/>
  </joint>
  <!-- Transmission elements required for Gazebo -->
  <transmission name="transmission_4">
    <type>transmission_interface/SimpleTransmission</type>
    <joint name="4">
      <hardwareInterface>hardware_interface/EffortJointInterface</hardwareInterface>
    </joint>
    <actuator name="motor_4">
      <hardwareInterface>EffortJointInterface</hardwareInterface>
      <mechanicalReduction>1</mechanicalReduction>
    </actuator>
  </transmission>
  <!-- Lower leg -->
  <link name="knee,fr">
    <visual>
      <origin rpy="1.5707963267948966 0 1.5707963267948966" xyz="0.135 0 0"/>
      <geometry>
        <cylinder length="0.27" radius="0.011"/>
      </geometry>
      <material name="gray"/>
    </visual>
    <collision>
      <origin rpy="1.5707963267948966 0 1.5707963267948966" xyz="0.135 0 -0.0"/>
      <geometry>
        <cylinder length="0.27" radius="0.011"/>
      </geometry>
    </collision>
    <inertial>
      <mass value="0.28"/>
      <inertia ixx="0.0665" ixy="0" ixz="0" iyy="0.0032" iyz="0" izz="0.0032"/>
    </inertial>
  </link>
  <gazebo reference="knee,fr">
    <material>Gazebo/Black</material>
  </gazebo>
  <!-- Knee joint. Joint names are: 1 3 5 7 -->
  <joint name="5" type="revolute">
    <parent link="hip2,fr"/>
    <child link="knee,fr"/>
    <axis xyz="0 0 -1"/>
    <origin rpy="0 0 3.141592653589793" xyz="0.222 0 0.03"/>
    <limit effort="87.5" lower="0" upper="3.141592653589793" velocity="30"/>
    <dynamics damping="0.0" friction="0.0"/>
  </joint>
  <!-- Transmission elements required for Gazebo -->
  <transmission name="transmission_5">
    <type>transmission_interface/SimpleTransmission</type>
    <joint name="5">
      <hardwareInterface>hardware_interface/EffortJointInterface</hardwareInterface>
    </joint>
    <actuator name="motor_5">
      <hardwareInterface>EffortJointInterface</hardwareInterface>
      <mechanicalReduction>1</mechanicalReduction>
    </actuator>
  </transmission>
  

		Toe 
		
  <link name="foot,fr">
    <!--<visual>
				<origin rpy="0 0 0" xyz="0 0 0"/>
				<geometry>
					<sphere radius="${toeRadius}"/>
				</geometry>
			</visual>
			
			<collision>
				<origin rpy="0 0 0" xyz="0 0 0"/>
				<geometry>
					<sphere radius="${toeRadius}"/>
				</geometry>
			</collision>

			<inertial>
				<mass value="${toeMass}"/>
				<inertia ixx="0.000025"  ixy="0"  ixz="0" iyy="0.000025" iyz="0" izz="0.000025" />
			</inertial>
			-->
  </link>
  <gazebo reference="foot,fr">
    <material>Gazebo/DarkGray</material>
    <collision>
      <surface>
        <bounce>
          <restitution_coefficient>0</restitution_coefficient>
          <threshold>1e+06</threshold>
        </bounce>
        <friction>
          <torsional>
            <coefficient>0.3</coefficient>
          </torsional>
          <ode>
            <mu>20.0</mu>
            <mu2>10.0</mu2>
          </ode>
          <bullet>
            <rolling_friction>0.3</rolling_friction>
            <friction2>10.0</friction2>
          </bullet>
        </friction>
        <contact>
          <bullet>
            <kp>30000.0</kp>
            <kd>1000.0</kd>
          </bullet>
          <ode>
            <kp>30000.0</kp>
            <kd>1000.0</kd>
          </ode>
        </contact>
      </surface>
    </collision>
  </gazebo>
  <joint name="jtoe,fr" type="fixed">
    <parent link="knee,fr"/>
    <child link="foot,fr"/>
    <origin xyz="0.27 0 0"/>
    <dynamics damping="0.0" friction="0.0"/>
  </joint>
  <!-- Hip motor -->
  <link name="hip1,rr">
    <visual>
      <origin rpy="0 0 0" xyz="0.065 0.03 0"/>
      <geometry>
        <box size="0.13 0.09 0.07"/>
      </geometry>
      <material name="gray"/>
    </visual>
    <collision>
      <origin rpy="0 0 0" xyz="0.065 0.03 0"/>
      <geometry>
        <box size="0.13 0.09 0.07"/>
      </geometry>
    </collision>
    <inertial>
      <mass value="1.18"/>
      <inertia ixx="0.0299" ixy="0" ixz="0" iyy="0.0333" iyz="0" izz="0.0046"/>
    </inertial>
  </link>
  <gazebo reference="hip1,rr">
    <material>Gazebo/Purple</material>
  </gazebo>
  <!-- Abduction joint. Joint names are: 8 9 10 11 -->
  <joint name="11" type="revolute">
    <parent link="base"/>
    <child link="hip1,rr"/>
    <axis xyz="0 0 1"/>
    <origin rpy="0 0 3.141592653589793" xyz="-0.15121 -0.15121 0"/>
    <limit effort="375" lower="-0.39269908169872414" upper="1.5707963267948966" velocity="8.6"/>
    <dynamics damping="0.0" friction="0.0"/>
  </joint>
  <!-- Transmission elements required for Gazebo -->
  <transmission name="transmission_11">
    <type>transmission_interface/SimpleTransmission</type>
    <joint name="11">
      <hardwareInterface>hardware_interface/EffortJointInterface</hardwareInterface>
    </joint>
    <actuator name="motor_11">
      <hardwareInterface>EffortJointInterface</hardwareInterface>
      <mechanicalReduction>1</mechanicalReduction>
    </actuator>
  </transmission>
  <!-- Upper leg -->
  <link name="hip2,rr">
    <visual>
      <origin rpy="1.5707963267948966 0 0" xyz="0.111 0 -0.03"/>
      <geometry>
        <box size="0.222 0.044 0.06"/>
      </geometry>
      <material name="gray"/>
    </visual>
    <collision>
      <origin rpy="0 0 0" xyz="0.111 0 -0.03"/>
      <geometry>
        <box size="0.222 0.044 0.06"/>
      </geometry>
    </collision>
    <inertial>
      <mass value="1.39"/>
      <inertia ixx="0.0017" ixy="0" ixz="0" iyy="0.0066" iyz="0" izz="0.0064"/>
    </inertial>
  </link>
  <gazebo reference="hip2,rr">
    <material>Gazebo/Blue</material>
  </gazebo>
  <!-- Hip joint. (Motor to upper leg). Joint names are: 0 2 4 6 -->
  <joint name="6" type="revolute">
    <parent link="hip1,rr"/>
    <child link="hip2,rr"/>
    <axis xyz="0 0 1"/>
    <origin rpy="-1.5707963267948966 0 0" xyz="0.13 0.03 0"/>
    <limit effort="87.5" lower="-1.5707963267948966" upper="2.356194490192345" velocity="30"/>
    <dynamics damping="0.0" friction="0.0"/>
  </joint>
  <!-- Transmission elements required for Gazebo -->
  <transmission name="transmission_6">
    <type>transmission_interface/SimpleTransmission</type>
    <joint name="6">
      <hardwareInterface>hardware_interface/EffortJointInterface</hardwareInterface>
    </joint>
    <actuator name="motor_6">
      <hardwareInterface>EffortJointInterface</hardwareInterface>
      <mechanicalReduction>1</mechanicalReduction>
    </actuator>
  </transmission>
  <!-- Lower leg -->
  <link name="knee,rr">
    <visual>
      <origin rpy="1.5707963267948966 0 1.5707963267948966" xyz="0.135 0 0"/>
      <geometry>
        <cylinder length="0.27" radius="0.011"/>
      </geometry>
      <material name="gray"/>
    </visual>
    <collision>
      <origin rpy="1.5707963267948966 0 1.5707963267948966" xyz="0.135 0 -0.0"/>
      <geometry>
        <cylinder length="0.27" radius="0.011"/>
      </geometry>
    </collision>
    <inertial>
      <mass value="0.28"/>
      <inertia ixx="0.0665" ixy="0" ixz="0" iyy="0.0032" iyz="0" izz="0.0032"/>
    </inertial>
  </link>
  <gazebo reference="knee,rr">
    <material>Gazebo/Black</material>
  </gazebo>
  <!-- Knee joint. Joint names are: 1 3 5 7 -->
  <joint name="7" type="revolute">
    <parent link="hip2,rr"/>
    <child link="knee,rr"/>
    <axis xyz="0 0 -1"/>
    <origin rpy="0 0 3.141592653589793" xyz="0.222 0 -0.03"/>
    <limit effort="87.5" lower="0" upper="3.141592653589793" velocity="30"/>
    <dynamics damping="0.0" friction="0.0"/>
  </joint>
  <!-- Transmission elements required for Gazebo -->
  <transmission name="transmission_7">
    <type>transmission_interface/SimpleTransmission</type>
    <joint name="7">
      <hardwareInterface>hardware_interface/EffortJointInterface</hardwareInterface>
    </joint>
    <actuator name="motor_7">
      <hardwareInterface>EffortJointInterface</hardwareInterface>
      <mechanicalReduction>1</mechanicalReduction>
    </actuator>
  </transmission>
  

		Toe 
		
  <link name="foot,rr">
    <!--<visual>
				<origin rpy="0 0 0" xyz="0 0 0"/>
				<geometry>
					<sphere radius="${toeRadius}"/>
				</geometry>
			</visual>
			
			<collision>
				<origin rpy="0 0 0" xyz="0 0 0"/>
				<geometry>
					<sphere radius="${toeRadius}"/>
				</geometry>
			</collision>

			<inertial>
				<mass value="${toeMass}"/>
				<inertia ixx="0.000025"  ixy="0"  ixz="0" iyy="0.000025" iyz="0" izz="0.000025" />
			</inertial>
			-->
  </link>
  <gazebo reference="foot,rr">
    <material>Gazebo/DarkGray</material>
    <collision>
      <surface>
        <bounce>
          <restitution_coefficient>0</restitution_coefficient>
          <threshold>1e+06</threshold>
        </bounce>
        <friction>
          <torsional>
            <coefficient>0.3</coefficient>
          </torsional>
          <ode>
            <mu>20.0</mu>
            <mu2>10.0</mu2>
          </ode>
          <bullet>
            <rolling_friction>0.3</rolling_friction>
            <friction2>10.0</friction2>
          </bullet>
        </friction>
        <contact>
          <bullet>
            <kp>30000.0</kp>
            <kd>1000.0</kd>
          </bullet>
          <ode>
            <kp>30000.0</kp>
            <kd>1000.0</kd>
          </ode>
        </contact>
      </surface>
    </collision>
  </gazebo>
  <joint name="jtoe,rr" type="fixed">
    <parent link="knee,rr"/>
    <child link="foot,rr"/>
    <origin xyz="0.27 0 0"/>
    <dynamics damping="0.0" friction="0.0"/>
  </joint>
  <!-- Add ros_control plugin -->
  <gazebo>
    <plugin filename="libgazebo_ros_control.so" name="gazebo_ros_control">
      <robotNamespace>/ASTRo</robotNamespace>
    </plugin>
  </gazebo>
</robot>

